<?xml version='1.0'?>
    <sdf version='1.4'>
      <model name="my_robot">
      
      <static>false</static>
      
      <link name='chassis'>
          <pose>0 0 .1 0 0 0</pose>
          <inertial>
            <mass>10.0</mass>
            <inertia>
              <ixx>0.100982</ixx>
              <ixy>0</ixy>
              <ixz>0.00196078</ixz>
              <iyy>0.104904</iyy>
              <iyz>0</iyz>
              <izz>0.103924</izz>
            </inertia>
          </inertial>
          <collision name='collision'>
            <geometry>
              <box>
                <size>.4 .2 .1</size>
              </box>
            </geometry>
          </collision>

          <visual name='visual'>
            <geometry>
              <box>
                <size>.4 .2 .1</size>
              </box>
            </geometry>
            <material>
               <script>
                  <uri>file://media/materials/scripts/gazebo.material</uri>
                  <name>Gazebo/Red</name>
               </script>
            </material>
          
          </visual>

          <collision name='caster_collision'>
            <pose>0.15 0 -0.05 0 0 0</pose>
            <geometry>
              <sphere>
              <radius>.05</radius>
            </sphere>
          </geometry>

          <surface>
            <friction>
              <ode>
                <mu>0</mu>
                <mu2>0</mu2>
                <slip1>1.0</slip1>
                <slip2>1.0</slip2>
              </ode>
            </friction>
          </surface>
        </collision>

        <visual name='caster_visual'>
          <pose>0.15 0 -0.05 0 0 0</pose>
          <geometry>
            <sphere>
              <radius>.05</radius>
            </sphere>
          </geometry>
          <material>
            <script>
               <uri>file://media/materials/scripts/gazebo.material</uri>
               <name>Gazebo/Black</name>
            </script>
          </material>
        </visual>
       <sensor name="imu_sensor" type="imu">
        <always_on>true</always_on>
        <update_rate>100</update_rate>
        <visualize>true</visualize>
        <topic>__default_topic__</topic>
      <plugin filename="libgazebo_ros_imu_sensor.so" name="imu_plugin">
        <topicName>imu</topicName>
        <bodyName>chassis</bodyName>
        <updateRateHZ>100.0</updateRateHZ>
        <gaussianNoise>0.0</gaussianNoise>
        <xyzOffset>0 0 0</xyzOffset>
        <rpyOffset>0 0 0</rpyOffset>
        <frameName>imu_link</frameName>
        <initialOrientationAsReference>false</initialOrientationAsReference>
      </plugin>
      <pose>0 0 0 0 0 0</pose>
    </sensor>
        
      </link>
      <link name="left_wheel">
        <pose>-0.1 0.13 0.1 0 1.5707 1.5707</pose>
        <inertial>
          <mass>5</mass>
          <inertia>
            <ixx>0.1</ixx>
            <ixy>0</ixy>
            <ixz>0</ixz>
            <iyy>0.1</iyy>
            <iyz>0</iyz>
            <izz>0.1</izz>
          </inertia>
        </inertial>
        <collision name="collision">
          <geometry>
            <cylinder>
              <radius>.1</radius>
              <length>.05</length>
            </cylinder>
          </geometry>
        </collision>
        <visual name="visual">
          <geometry>
            <cylinder>
              <radius>.1</radius>
              <length>.05</length>
            </cylinder>
          </geometry>
          <material>
            <script>
               <uri>file://media/materials/scripts/gazebo.material</uri>
               <name>Gazebo/Black</name>
            </script>
          </material>
        </visual>
      </link>

      <link name="right_wheel">
        <pose>-0.1 -0.13 0.1 0 1.5707 1.5707</pose>
        <inertial>
          <mass>5</mass>
          <inertia>
            <ixx>0.1</ixx>
            <ixy>0</ixy>
            <ixz>0</ixz>
            <iyy>0.1</iyy>
            <iyz>0</iyz>
            <izz>0.1</izz>
          </inertia>
        </inertial>
        <collision name="collision">
          <geometry>
            <cylinder>
              <radius>.1</radius>
              <length>.05</length>
            </cylinder>
          </geometry>
        </collision>
        <visual name="visual">
          <geometry>
            <cylinder>
              <radius>.1</radius>
              <length>.05</length>
            </cylinder>
          </geometry>
          <material>
            <script>
               <uri>file://media/materials/scripts/gazebo.material</uri>
               <name>Gazebo/Black</name>
            </script>
          </material>
        </visual>
      </link>
      
      <link name='hokuyo_link'>
          <pose>0.175 0 .175 0 0 0</pose>
          <inertial>
            <mass>1e-5</mass>
            <inertia>
              <ixx>1e-6</ixx>
              <ixy>0</ixy>
              <ixz>0</ixz>
              <iyy>1e-6</iyy>
              <iyz>0</iyz>
              <izz>1e-6</izz>
            </inertia>
          </inertial>
          
          <collision name='collision'>
            <geometry>
              <box>
                <size>.1 .1 .1</size>
              </box>
            </geometry>
          </collision>

          <visual name='visual'>
            <geometry>
            <mesh>
              <uri>model://hokuyo/meshes/hokuyo.dae</uri>
            </mesh>
            </geometry>
          </visual>
     <sensor type="ray" name="head_hokuyo_sensor">
      <pose>0 0 0 0 0 0</pose>
      <visualize>true</visualize>
      <update_rate>40</update_rate>
      <ray>
        <scan>
          <horizontal>
            <samples>720</samples>
            <resolution>1</resolution>
            <min_angle>-0.785</min_angle>
            <max_angle>1.785</max_angle>
          </horizontal>
        </scan>
        <range>
          <min>0.10</min>
          <max>30.0</max>
          <resolution>0.01</resolution>
        </range>
        <noise>
          <type>gaussian</type>
          <!-- Noise parameters based on published spec for Hokuyo laser
               achieving "+-30mm" accuracy at range < 10m.  A mean of 0.0m and
               stddev of 0.01m will put 99.7% of samples within 0.03m of the true
               reading. -->
          <mean>0.0</mean>
          <stddev>0.01</stddev>
        </noise>
      </ray>
      <plugin name="gazebo_ros_head_hokuyo_controller" filename="libgazebo_ros_laser.so">
        <topicName>/laser/scan</topicName>
        <frameName>hokuyo_link</frameName>
      </plugin>
    </sensor>
       </link>

      <joint type="revolute" name="left_wheel_hinge">
        <pose>0 0 -0.03 0 0 0</pose>
        <child>left_wheel</child>
        <parent>chassis</parent>
        <axis>
          <xyz>0 1 0</xyz>
        </axis>
        <dynamics>
          <spring_reference>0</spring_reference>
          <spring_stiffness>0</spring_stiffness>
        </dynamics>
      </joint>

      <joint type="revolute" name="right_wheel_hinge">
        <pose>0 0 0.03 0 0 0</pose>
        <child>right_wheel</child>
        <parent>chassis</parent>
        <axis>
          <xyz>0 1 0</xyz>
        </axis>
        <dynamics>
          <spring_reference>0</spring_reference>
          <spring_stiffness>0</spring_stiffness>
        </dynamics>
      </joint>
      <joint name="hokuyo_joint" type="fixed">
        <pose>0 0 0 0 0 0</pose>
        <child>hokuyo_link</child>
        <parent>chassis</parent>
      </joint>
      
      <!-- Default plugin for the differential drive controller -->
      <plugin name="differential_drive_controller" filename="libgazebo_ros_diff_drive.so">
        <!-- Plugin update rate in Hz -->
        <updateRate>100</updateRate>
        <!-- Name of joints -->
        <leftJoint>left_wheel_hinge</leftJoint>
        <rightJoint>right_wheel_hinge</rightJoint>
        <!-- The distance from the center of one wheel to the other, in meters, defaults to 0.34 m -->
        <wheelSeparation>0.26</wheelSeparation>
        <!-- Diameter of the wheels, in meters, defaults to 0.15 m -->
        <wheelDiameter>0.2</wheelDiameter>
        <!-- 1.0 Wheel acceleration, in rad/s^2, defaults to 0.0 rad/s^2 -->
        <wheelAcceleration>10.0</wheelAcceleration>
        <!-- 20 Maximum torque which the wheels can produce, in Nm, defaults to 5 Nm -->
        <wheelTorque>100</wheelTorque>
        <!-- Topic to receive geometry_msgs/Twist message commands, defaults to `cmd_vel` -->
        <commandTopic>cmd_vel</commandTopic>
        <!-- Topic to publish nav_msgs/Odometry messages, defaults to `odom` -->
        <odometryTopic>odom</odometryTopic>
        <!-- Odometry frame, defaults to `odom` -->
        <odometryFrame>odom</odometryFrame>
        <!-- Robot frame to calculate odometry from, defaults to `base_footprint` -->
        <robotBaseFrame>base_footprint</robotBaseFrame>
        <!-- Odometry source, 0 for ENCODER, 1 for WORLD, defaults to WORLD -->
        <odometrySource>1</odometrySource>
        <!-- Set to true to publish transforms for the wheel links, defaults to false -->
        <publishWheelTF>true</publishWheelTF>
        <!-- Set to true to publish transforms for the odometry, defaults to true -->
        <publishOdomTF>true</publishOdomTF>
        <!-- Set to true to publish sensor_msgs/JointState on /joint_states for the wheel joints, defaults to false -->
        <publishWheelJointState>true</publishWheelJointState>
        <!-- Set to true to swap right and left wheels, defaults to true -->
        <legacyMode>true</legacyMode>
      </plugin>
      
  </model>
</sdf>
      
      
      
